Workbook

Sheet Sheet1
A1: VEGETABLES
A2: ITEM | B2: Rate per KG | C2: 46174 | D2: 46175 | E2: 46176 | F2: 46177 | G2: 46178 | H2: 46179 | I2: 46180 | J2: 46181 | K2: 46182 | L2: 46183 | M2: 46184 | N2: 46185 | O2: 46186 | P2: 46187 | Q2: 46188 | R2: 46189 | S2: 46190 | T2: 46191 | U2: 46192 | V2: 46193 | W2: 46194 | X2: 46195 | Y2: 46196 | Z2: 46197 | AA2: 46198 | AB2: 46199 | AC2: 46200 | AD2: 46201 | AE2: 46202 | AF2: 46203 | AH2: TOTAL KG | AI2: TOTAL
A3: ONION | B3: 30 | C3: 50 | F3: 50 | H3: 99 | AH3: =SUM(C3:AF3) | AI3: =SUM(C3:AF3)*B3
A4: TOMATO | B4: 20 | C4: 20 | E4: 15 | F4: 15 | G4: 25 | H4: 15 | I4: 20 | J4: 25 | L4: 25 | AH4: =SUM(C4:AF4) | AI4: =SUM(C4:AF4)*B4
A5: AALO | B5: 15 | C5: 5 | E5: 5 | G5: 5 | H5: 5 | L5: 5 | AH5: =SUM(C5:AF5) | AI5: =SUM(C5:AF5)*B5
A6: SHIMLA | B6: 49 | C6: 3 | E6: 3 | F6: 3 | G6: 2 | H6: 2.5 | I6: 7 | J6: 5 | L6: 2 | AH6: =SUM(C6:AF6) | AI6: =SUM(C6:AF6)*B6
A7: CABBAGE | B7: 20 | C7: 2 | G7: 5 | H7: 1 | I7: 1 | J7: 2 | AH7: =SUM(C7:AF7) | AI7: =SUM(C7:AF7)*B7
A8: BEANS | B8: 120 | F8: 1 | J8: 0.5 | AH8: =SUM(C8:AF8) | AI8: =SUM(C8:AF8)*B8
A9: GAJAR | B9: 40 | C9: 0.5 | E9: 0.5 | F9: 0.5 | G9: 0.5 | H9: 0.5 | J9: 0.5 | L9: 0.5 | AH9: =SUM(C9:AF9) | AI9: =SUM(C9:AF9)*B9
A10: GARLIC | B10: 120 | C10: 2 | E10: 2 | F10: 1 | G10: 2.5 | H10: 2 | I10: 2.5 | J10: 4 | L10: 2 | AH10: =SUM(C10:AF10) | AI10: =SUM(C10:AF10)*B10
A11: GINGER | B11: 50 | C11: 1 | E11: 1 | F11: 1 | G11: 1 | H11: 1 | I11: 1 | J11: 1 | L11: 1 | AH11: =SUM(C11:AF11) | AI11: =SUM(C11:AF11)*B11
A12: DHANIYA | B12: 50 | C12: 1.5 | E12: 2 | F12: 0.5 | G12: 0.5 | I12: 0.5 | J12: 1 | L12: 0.5 | AH12: =SUM(C12:AF12) | AI12: =SUM(C12:AF12)*B12
A13: HARI MIRCH | B13: 40 | C13: 1 | E13: 1 | F13: 1.5 | G13: 1.5 | H13: 1 | I13: 1 | J13: 3 | AH13: =SUM(C13:AF13) | AI13: =SUM(C13:AF13)*B13
A14: LEMON | B14: 90 | C14: 0.5 | E14: 0.5 | F14: 0.5 | H14: 0.5 | I14: 1 | J14: 0.5 | AH14: =SUM(C14:AF14) | AI14: =SUM(C14:AF14)*B14
A15: PUDINA | B15: 80 | C15: 0.5 | F15: 0.25 | AH15: =SUM(C15:AF15) | AI15: =SUM(C15:AF15)*B15
A16: MUSHROOM | B16: 80 | C16: 2 | E16: 2 | F16: 2 | H16: 2 | I16: 2 | J16: 2 | AH16: =SUM(C16:AF16) | AI16: =SUM(C16:AF16)*B16
A17: KHEERA | B17: 30 | I17: 1 | AH17: =SUM(C17:AF17) | AI17: =SUM(C17:AF17)*B17
A18: HARA PYAZ | L18: 0.5
A20: TOTAL | AI20: =SUM(AI3:AI18)
A25: CHICKEN
A26: ITEM | B26: Rate per KG | C26: 46174 | D26: 46175 | E26: 46176 | F26: 46177 | G26: 46178 | H26: 46179 | I26: 46180 | J26: 46181 | K26: 46182 | L26: 46183 | M26: 46184 | N26: 46185 | O26: 46186 | P26: 46187 | Q26: 46188 | R26: 46189 | S26: 46190 | T26: 46191 | U26: 46192 | V26: 46193 | W26: 46194 | X26: 46195 | Y26: 46196 | Z26: 46197 | AA26: 46198 | AB26: 46199 | AC26: 46200 | AD26: 46201 | AE26: 46202 | AF26: 46203 | AI26: TOTAL
A28: TANDORI | B28: 160 | C28: 10 | E28: 10 | F28: 10 | G28: 10 | H28: 15 | I28: 10 | J28: 10 | L28: 10 | AH28: =SUM(C28:AF28) | AI28: =SUM(C28:AF28)*B28
A29: THAI | B29: 260 | C29: 5 | E29: 3 | F29: 5 | G29: 2 | H29: 7 | I29: 2 | J29: 5 | L29: 5 | AH29: =SUM(C29:AF29) | AI29: =SUM(C29:AF29)*B29
A30: TANGRI | B30: 220 | C30: 1 | F30: 1 | H30: 1 | J30: 1 | AH30: =SUM(C30:AF30) | AI30: =SUM(C30:AF30)*B30
A31: CHEST | B31: 220 | AH31: =SUM(C31:AF31) | AI31: =SUM(C31:AF31)*B31
AH32: =SUM(C32:AF32) | AI32: =SUM(C32:AF32)*B32
A34: TOTAL | AI34: =SUM(AI28:AI32)
A39: CHICKEN
A40: ITEM | B40: Rate per KG | C40: 46174 | D40: 46175 | E40: 46176 | F40: 46177 | G40: 46178 | H40: 46179 | I40: 46180 | J40: 46181 | K40: 46182 | L40: 46183 | M40: 46184 | N40: 46185 | O40: 46186 | P40: 46187 | Q40: 46188 | R40: 46189 | S40: 46190 | T40: 46191 | U40: 46192 | V40: 46193 | W40: 46194 | X40: 46195 | Y40: 46196 | Z40: 46197 | AA40: 46198 | AB40: 46199 | AC40: 46200 | AD40: 46201 | AE40: 46202 | AF40: 46203 | AI40: TOTAL
A42: PANEER | B42: 220 | C42: 3 | E42: 5 | F42: 5 | H42: 5 | I42: 2 | J42: 5 | L42: 5 | AH42: =SUM(C42:AF42) | AI42: =SUM(C42:AF42)*B42
A43: CHAAP | B43: 60 | C43: 15 | E43: 15 | F43: 10 | G43: 10 | H43: 10 | I43: 10 | J43: 15 | K43: 10 | L43: 10 | AH43: =SUM(C43:AF43) | AI43: =SUM(C43:AF43)*B43
A44: DAHI | B44: 60 | C44: 10 | E44: 10 | F44: 5 | G44: 10 | H44: 5 | I44: 10 | J44: 5 | AH44: =SUM(C44:AF44) | AI44: =SUM(C44:AF44)*B44
A45: NUTRILITE | B45: 180 | C45: 2 | E45: 2 | F45: 1 | G45: 2 | I45: 2 | J45: 2 | AH45: =SUM(C45:AF45) | AI45: =SUM(C45:AF45)*B45
A46: NOODLES | B46: 45 | C46: 2 | G46: 2 | AH46: =SUM(C46:AF46) | AI46: =SUM(C46:AF46)*B46
A47: MILK | B47: 60 | C47: 2 | E47: 2 | F47: 2 | G47: 2 | H47: 2 | I47: 2 | J47: 2 | L47: 2 | AH47: =SUM(C47:AF47) | AI47: =SUM(C47:AF47)*B47
A48: MATAR | AH48: =SUM(C48:AF48) | AI48: =SUM(C48:AF48)*B48
A50: TOTAL | AI50: =SUM(AI42:AI48)
A56: RASHAN
A57: ITEM | B57: Rate per KG | C57: 46174 | D57: 46175 | E57: 46176 | F57: 46177 | G57: 46178 | H57: 46179 | I57: 46180 | J57: 46181 | K57: 46182 | L57: 46183 | M57: 46184 | N57: 46185 | O57: 46186 | P57: 46187 | Q57: 46188 | R57: 46189 | S57: 46190 | T57: 46191 | U57: 46192 | V57: 46193 | W57: 46194 | X57: 46195 | Y57: 46196 | Z57: 46197 | AA57: 46198 | AB57: 46199 | AC57: 46200 | AD57: 46201 | AE57: 46202 | AF57: 46203 | AH57: TOTAL KG | AI57: TOTAL
A58: REFINED | B58: 1610 | C58: 1 | E58: 1 | G58: 1 | H58: 1 | I58: 1 | AH58: =SUM(C58:AF58) | AI58: =SUM(C58:AF58)*B58
...

Sheet Sheet2
A1: RDC STOCK MANAGEMENT DASHBOARD
A2: Month: June 2026 Period: 01 Jun – 30 Jun 2026 | E2: Updated: 10-Jun-2026
A4: MONTHLY EXPENSE SUMMARY
A5: # | B5: CATEGORY | C5: TOTAL AMOUNT (Rs.) | D5: % OF TOTAL
A6: 1 | B6: VEGETABLES | C6: =Sheet1!AI20 | D6: =IFERROR(E6/=SUM(E6:E10)*100,0)
A7: 2 | B7: CHICKEN (Raw) | C7: =Sheet1!AI34 | D7: =IFERROR(E7/=SUM(E6:E10)*100,0)
A8: 3 | B8: PANEER & DAIRY | C8: =Sheet1!AI50 | D8: =IFERROR(E8/=SUM(E6:E10)*100,0)
A9: 4 | B9: RASHAN | C9: =Sheet1!AI104 | D9: =IFERROR(E9/=SUM(E6:E10)*100,0)
A10: 5 | B10: DISPOSAL | C10: =Sheet1!AI136 | D10: =IFERROR(E10/=SUM(E6:E10)*100,0)
B11: GRAND TOTAL | C11: =SUM(E6:E10) | D11: 100.0%
A13: VEGETABLES
A14: # | B14: ITEM NAME | C14: RATE / KG (Rs.) | D14: TOTAL QTY (KG/Unit) | E14: TOTAL AMOUNT (Rs.) | F14: % SHARE
A15: 1 | B15: =Sheet1!A3 | C15: =IF(ISNUMBER(Sheet1!B3),Sheet1!B3,"") | D15: =IF(ISNUMBER(Sheet1!AH3),Sheet1!AH3,"") | E15: =IF(ISNUMBER(Sheet1!AI3),Sheet1!AI3,"") | F15: =IFERROR(IF(ISNUMBER(Sheet1!AI3),Sheet1!AI3,0)/Sheet1!AI20*100,0)
A16: 2 | B16: =Sheet1!A4 | C16: =IF(ISNUMBER(Sheet1!B4),Sheet1!B4,"") | D16: =IF(ISNUMBER(Sheet1!AH4),Sheet1!AH4,"") | E16: =IF(ISNUMBER(Sheet1!AI4),Sheet1!AI4,"") | F16: =IFERROR(IF(ISNUMBER(Sheet1!AI4),Sheet1!AI4,0)/Sheet1!AI20*100,0)
A17: 3 | B17: =Sheet1!A5 | C17: =IF(ISNUMBER(Sheet1!B5),Sheet1!B5,"") | D17: =IF(ISNUMBER(Sheet1!AH5),Sheet1!AH5,"") | E17: =IF(ISNUMBER(Sheet1!AI5),Sheet1!AI5,"") | F17: =IFERROR(IF(ISNUMBER(Sheet1!AI5),Sheet1!AI5,0)/Sheet1!AI20*100,0)
A18: 4 | B18: =Sheet1!A6 | C18: =IF(ISNUMBER(Sheet1!B6),Sheet1!B6,"") | D18: =IF(ISNUMBER(Sheet1!AH6),Sheet1!AH6,"") | E18: =IF(ISNUMBER(Sheet1!AI6),Sheet1!AI6,"") | F18: =IFERROR(IF(ISNUMBER(Sheet1!AI6),Sheet1!AI6,0)/Sheet1!AI20*100,0)
A19: 5 | B19: =Sheet1!A7 | C19: =IF(ISNUMBER(Sheet1!B7),Sheet1!B7,"") | D19: =IF(ISNUMBER(Sheet1!AH7),Sheet1!AH7,"") | E19: =IF(ISNUMBER(Sheet1!AI7),Sheet1!AI7,"") | F19: =IFERROR(IF(ISNUMBER(Sheet1!AI7),Sheet1!AI7,0)/Sheet1!AI20*100,0)
A20: 6 | B20: =Sheet1!A8 | C20: =IF(ISNUMBER(Sheet1!B8),Sheet1!B8,"") | D20: =IF(ISNUMBER(Sheet1!AH8),Sheet1!AH8,"") | E20: =IF(ISNUMBER(Sheet1!AI8),Sheet1!AI8,"") | F20: =IFERROR(IF(ISNUMBER(Sheet1!AI8),Sheet1!AI8,0)/Sheet1!AI20*100,0)
A21: 7 | B21: =Sheet1!A9 | C21: =IF(ISNUMBER(Sheet1!B9),Sheet1!B9,"") | D21: =IF(ISNUMBER(Sheet1!AH9),Sheet1!AH9,"") | E21: =IF(ISNUMBER(Sheet1!AI9),Sheet1!AI9,"") | F21: =IFERROR(IF(ISNUMBER(Sheet1!AI9),Sheet1!AI9,0)/Sheet1!AI20*100,0)
A22: 8 | B22: =Sheet1!A10 | C22: =IF(ISNUMBER(Sheet1!B10),Sheet1!B10,"") | D22: =IF(ISNUMBER(Sheet1!AH10),Sheet1!AH10,"") | E22: =IF(ISNUMBER(Sheet1!AI10),Sheet1!AI10,"") | F22: =IFERROR(IF(ISNUMBER(Sheet1!AI10),Sheet1!AI10,0)/Sheet1!AI20*100,0)
A23: 9 | B23: =Sheet1!A11 | C23: =IF(ISNUMBER(Sheet1!B11),Sheet1!B11,"") | D23: =IF(ISNUMBER(Sheet1!AH11),Sheet1!AH11,"") | E23: =IF(ISNUMBER(Sheet1!AI11),Sheet1!AI11,"") | F23: =IFERROR(IF(ISNUMBER(Sheet1!AI11),Sheet1!AI11,0)/Sheet1!AI20*100,0)
A24: 10 | B24: =Sheet1!A12 | C24: =IF(ISNUMBER(Sheet1!B12),Sheet1!B12,"") | D24: =IF(ISNUMBER(Sheet1!AH12),Sheet1!AH12,"") | E24: =IF(ISNUMBER(Sheet1!AI12),Sheet1!AI12,"") | F24: =IFERROR(IF(ISNUMBER(Sheet1!AI12),Sheet1!AI12,0)/Sheet1!AI20*100,0)
A25: 11 | B25: =Sheet1!A13 | C25: =IF(ISNUMBER(Sheet1!B13),Sheet1!B13,"") | D25: =IF(ISNUMBER(Sheet1!AH13),Sheet1!AH13,"") | E25: =IF(ISNUMBER(Sheet1!AI13),Sheet1!AI13,"") | F25: =IFERROR(IF(ISNUMBER(Sheet1!AI13),Sheet1!AI13,0)/Sheet1!AI20*100,0)
A26: 12 | B26: =Sheet1!A14 | C26: =IF(ISNUMBER(Sheet1!B14),Sheet1!B14,"") | D26: =IF(ISNUMBER(Sheet1!AH14),Sheet1!AH14,"") | E26: =IF(ISNUMBER(Sheet1!AI14),Sheet1!AI14,"") | F26: =IFERROR(IF(ISNUMBER(Sheet1!AI14),Sheet1!AI14,0)/Sheet1!AI20*100,0)
A27: 13 | B27: =Sheet1!A15 | C27: =IF(ISNUMBER(Sheet1!B15),Sheet1!B15,"") | D27: =IF(ISNUMBER(Sheet1!AH15),Sheet1!AH15,"") | E27: =IF(ISNUMBER(Sheet1!AI15),Sheet1!AI15,"") | F27: =IFERROR(IF(ISNUMBER(Sheet1!AI15),Sheet1!AI15,0)/Sheet1!AI20*100,0)
A28: 14 | B28: =Sheet1!A16 | C28: =IF(ISNUMBER(Sheet1!B16),Sheet1!B16,"") | D28: =IF(ISNUMBER(Sheet1!AH16),Sheet1!AH16,"") | E28: =IF(ISNUMBER(Sheet1!AI16),Sheet1!AI16,"") | F28: =IFERROR(IF(ISNUMBER(Sheet1!AI16),Sheet1!AI16,0)/Sheet1!AI20*100,0)
A29: 15 | B29: =Sheet1!A17 | C29: =IF(ISNUMBER(Sheet1!B17),Sheet1!B17,"") | D29: =IF(ISNUMBER(Sheet1!AH17),Sheet1!AH17,"") | E29: =IF(ISNUMBER(Sheet1!AI17),Sheet1!AI17,"") | F29: =IFERROR(IF(ISNUMBER(Sheet1!AI17),Sheet1!AI17,0)/Sheet1!AI20*100,0)
A30: 16 | B30: =Sheet1!A18 | C30: =IF(ISNUMBER(Sheet1!B18),Sheet1!B18,"") | D30: =IF(ISNUMBER(Sheet1!AH18),Sheet1!AH18,"") | E30: =IF(ISNUMBER(Sheet1!AI18),Sheet1!AI18,"") | F30: =IFERROR(IF(ISNUMBER(Sheet1!AI18),Sheet1!AI18,0)/Sheet1!AI20*100,0)
B31: SECTION TOTAL | E31: =Sheet1!AI20 | F31: 100.0%
A33: CHICKEN (Raw)
A34: # | B34: ITEM NAME | C34: RATE / KG (Rs.) | D34: TOTAL QTY (KG/Unit) | E34: TOTAL AMOUNT (Rs.) | F34: % SHARE
A35: 1 | B35: =Sheet1!A28 | C35: =IF(ISNUMBER(Sheet1!B28),Sheet1!B28,"") | D35: =IF(ISNUMBER(Sheet1!AH28),Sheet1!AH28,"") | E35: =IF(ISNUMBER(Sheet1!AI28),Sheet1!AI28,"") | F35: =IFERROR(IF(ISNUMBER(Sheet1!AI28),Sheet1!AI28,0)/Sheet1!AI34*100,0)
A36: 2 | B36: =Sheet1!A29 | C36: =IF(ISNUMBER(Sheet1!B29),Sheet1!B29,"") | D36: =IF(ISNUMBER(Sheet1!AH29),Sheet1!AH29,"") | E36: =IF(ISNUMBER(Sheet1!AI29),Sheet1!AI29,"") | F36: =IFERROR(IF(ISNUMBER(Sheet1!AI29),Sheet1!AI29,0)/Sheet1!AI34*100,0)
A37: 3 | B37: =Sheet1!A30 | C37: =IF(ISNUMBER(Sheet1!B30),Sheet1!B30,"") | D37: =IF(ISNUMBER(Sheet1!AH30),Sheet1!AH30,"") | E37: =IF(ISNUMBER(Sheet1!AI30),Sheet1!AI30,"") | F37: =IFERROR(IF(ISNUMBER(Sheet1!AI30),Sheet1!AI30,0)/Sheet1!AI34*100,0)
A38: 4 | B38: =Sheet1!A31 | C38: =IF(ISNUMBER(Sheet1!B31),Sheet1!B31,"") | D38: =IF(ISNUMBER(Sheet1!AH31),Sheet1!AH31,"") | E38: =IF(ISNUMBER(Sheet1!AI31),Sheet1!AI31,"") | F38: =IFERROR(IF(ISNUMBER(Sheet1!AI31),Sheet1!AI31,0)/Sheet1!AI34*100,0)
B39: SECTION TOTAL | E39: =Sheet1!AI34 | F39: 100.0%
A41: PANEER & DAIRY
A42: # | B42: ITEM NAME | C42: RATE / KG (Rs.) | D42: TOTAL QTY (KG/Unit) | E42: TOTAL AMOUNT (Rs.) | F42: % SHARE
A43: 1 | B43: =Sheet1!A42 | C43: =IF(ISNUMBER(Sheet1!B42),Sheet1!B42,"") | D43: =IF(ISNUMBER(Sheet1!AH42),Sheet1!AH42,"") | E43: =IF(ISNUMBER(Sheet1!AI42),Sheet1!AI42,"") | F43: =IFERROR(IF(ISNUMBER(Sheet1!AI42),Sheet1!AI42,0)/Sheet1!AI50*100,0)
A44: 2 | B44: =Sheet1!A43 | C44: =IF(ISNUMBER(Sheet1!B43),Sheet1!B43,"") | D44: =IF(ISNUMBER(Sheet1!AH43),Sheet1!AH43,"") | E44: =IF(ISNUMBER(Sheet1!AI43),Sheet1!AI43,"") | F44: =IFERROR(IF(ISNUMBER(Sheet1!AI43),Sheet1!AI43,0)/Sheet1!AI50*100,0)
...

Sheet Sheet3
